<robot name="phosphobot_so_100">
    <link name="Base_08q">
        <inertial>
            <mass value="0.0297539" />
            <origin xyz="-1.64205e-10 -0.0117384 0.0507125" rpy="0 -0 0" />
            <inertia ixx="0.0001" ixy="0.0" ixz="0.0" iyy="0.0001" iyz="-1.57469e-06" izz="0.0001" />
        </inertial>
        <visual>
            <origin xyz="0 0 0" rpy="0 -0 0" />
            <geometry>
                <mesh filename="package://so_arm100_description/meshes/67.stl" scale="1 1 1" />
            </geometry>
            <material name="0.329412_0.788235_0.113725_0.000000_0.000000">
                <texture />
                <color rgba="0.329412 0.788235 0.113725 1" />
            </material>
        </visual>
    </link>
    <link name="Base_08q_1">
        <inertial>
            <mass value="0.01" />
            <origin xyz="-4.60291e-20 -0.0548824 0.00981057" rpy="0 -0 0" />
            <inertia ixx="0.0001" ixy="0.0" ixz="0.0" iyy="0.0001" iyz="0.0" izz="0.0001" />
        </inertial>
        <visual>
            <origin xyz="0 0 0" rpy="0 -0 0" />
            <geometry>
                <mesh filename="package://so_arm100_description/meshes/71.stl" scale="1 1 1" />
            </geometry>
            <material name="0.329412_0.788235_0.113725_0.000000_0.000000">
                <texture />
                <color rgba="0.329412 0.788235 0.113725 1" />
            </material>
        </visual>
    </link>
    <link name="Base_08q_2">
        <inertial>
            <mass value="0.150854" />
            <origin xyz="-4.04437e-06 -0.0162574 0.0209951" rpy="0 -0 0" />
            <inertia ixx="0.000135299" ixy="0.0" ixz="0.0" iyy="0.00016103" iyz="-2.68213e-05" izz="0.000170081" />
        </inertial>
        <visual>
            <origin xyz="0 0 0" rpy="0 -0 0" />
            <geometry>
                <mesh filename="package://so_arm100_description/meshes/117.stl" scale="1 1 1" />
            </geometry>
            <material name="0.329412_0.788235_0.113725_0.000000_0.000000">
                <texture />
                <color rgba="0.329412 0.788235 0.113725 1" />
            </material>
        </visual>
        <collision><origin xyz="0 -0.015 0.04" rpy="0 0 0" /><geometry><box size="0.08 0.06 0.09" /></geometry></collision>
    </link>
    <link name="Driven horn">
        <inertial>
            <mass value="0.01" />
            <origin xyz="0 -0.00257016 -1.43155e-19" rpy="0 -0 0" />
            <inertia ixx="0.0001" ixy="0.0" ixz="0.0" iyy="0.0001" iyz="0.0" izz="0.0001" />
        </inertial>
        <visual>
            <origin xyz="-0.0125 0.0147 1.7455e-19" rpy="0 -0 0" />
            <geometry>
                <mesh filename="package://so_arm100_description/meshes/15661.stl" scale="1 1 1" />
            </geometry>
            <material name="0.917647_0.917647_0.917647_0.000000_0.000000">
                <texture />
                <color rgba="0.917647 0.917647 0.917647 1" />
            </material>
        </visual>
    </link>
    <link name="Driven horn_1">
        <inertial>
            <mass value="0.01" />
            <origin xyz="0 -0.00257016 -1.43155e-19" rpy="0 -0 0" />
            <inertia ixx="0.0001" ixy="0.0" ixz="0.0" iyy="0.0001" iyz="0.0" izz="0.0001" />
        </inertial>
        <visual>
            <origin xyz="-0.0125 0.0147 1.7455e-19" rpy="0 -0 0" />
            <geometry>
                <mesh filename="package://so_arm100_description/meshes/15661.stl" scale="1 1 1" />
            </geometry>
            <material name="0.917647_0.917647_0.917647_0.000000_0.000000">
                <texture />
                <color rgba="0.917647 0.917647 0.917647 1" />
            </material>
        </visual>
    </link>
    <link name="Driven horn_2">
        <inertial>
            <mass value="0.01" />
            <origin xyz="0 -0.00257016 -1.43155e-19" rpy="0 -0 0" />
            <inertia ixx="0.0001" ixy="0.0" ixz="0.0" iyy="0.0001" iyz="0.0" izz="0.0001" />
        </inertial>
        <visual>
            <origin xyz="-0.0125 0.0147 1.7455e-19" rpy="0 -0 0" />
            <geometry>
                <mesh filename="package://so_arm100_description/meshes/15661.stl" scale="1 1 1" />
            </geometry>
            <material name="0.917647_0.917647_0.917647_0.000000_0.000000">
                <texture />
                <color rgba="0.917647 0.917647 0.917647 1" />
            </material>
        </visual>
    </link>
    <link name="Driven horn_3">
        <inertial>
            <mass value="0.01" />
            <origin xyz="0 -0.00257016 -1.43155e-19" rpy="0 -0 0" />
            <inertia ixx="0.0001" ixy="0.0" ixz="0.0" iyy="0.0001" iyz="0.0" izz="0.0001" />
        </inertial>
        <visual>
            <origin xyz="-0.0125 0.0147 1.7455e-19" rpy="0 -0 0" />
            <geometry>
                <mesh filename="package://so_arm100_description/meshes/15661.stl" scale="1 1 1" />
            </geometry>
            <material name="0.917647_0.917647_0.917647_0.000000_0.000000">
                <texture />
                <color rgba="0.917647 0.917647 0.917647 1" />
            </material>
        </visual>
    </link>
    <link name="Driven horn_4">
        <inertial>
            <mass value="0.01" />
            <origin xyz="0 -0.00257016 -1.43155e-19" rpy="0 -0 0" />
            <inertia ixx="0.0001" ixy="0.0" ixz="0.0" iyy="0.0001" iyz="0.0" izz="0.0001" />
        </inertial>
        <visual>
            <origin xyz="-0.0125 0.0147 1.7455e-19" rpy="0 -0 0" />
            <geometry>
                <mesh filename="package://so_arm100_description/meshes/15661.stl" scale="1 1 1" />
            </geometry>
            <material name="0.917647_0.917647_0.917647_0.000000_0.000000">
                <texture />
                <color rgba="0.917647 0.917647 0.917647 1" />
            </material>
        </visual>
    </link>
    <link name="Driven horn_5">
        <inertial>
            <mass value="0.01" />
            <origin xyz="0 -0.00257016 -1.43155e-19" rpy="0 -0 0" />
            <inertia ixx="0.0001" ixy="0.0" ixz="0.0" iyy="0.0001" iyz="0.0" izz="0.0001" />
        </inertial>
        <visual>
            <origin xyz="-0.0125 0.0147 1.7455e-19" rpy="0 -0 0" />
            <geometry>
                <mesh filename="package://so_arm100_description/meshes/15661.stl" scale="1 1 1" />
            </geometry>
            <material name="0.917647_0.917647_0.917647_0.000000_0.000000">
                <texture />
                <color rgba="0.917647 0.917647 0.917647 1" />
            </material>
        </visual>
    </link>
    <link name="Moving_Jaw_08d">
        <inertial>
            <mass value="0.0252684" />
            <origin xyz="-0.00161987 -0.0192843 -0.0303966" rpy="0 -0 0" />
            <inertia ixx="0.0001" ixy="0.0" ixz="0.0" iyy="0.0001" iyz="0.0" izz="0.0001" />
        </inertial>
        <visual>
            <origin xyz="0 -0.0189 0" rpy="0 -0 0" />
            <geometry>
                <mesh filename="package://so_arm100_description/meshes/63.stl" scale="1 1 1" />
            </geometry>
            <material name="0.329412_0.788235_0.113725_0.000000_0.000000">
                <texture />
                <color rgba="0.329412 0.788235 0.113725 1" />
            </material>
        </visual>
        <collision><origin xyz="0 -0.02 -0.025" rpy="0 0 0" /><geometry><box size="0.035 0.02 0.045" /></geometry></collision>
    </link>
    <link name="Passive horn">
        <inertial>
            <mass value="0.01" />
            <origin xyz="2.25823e-20 0.00200132 -8.39298e-21" rpy="0 -0 0" />
            <inertia ixx="0.0001" ixy="0.0" ixz="0.0" iyy="0.0001" iyz="0.0" izz="0.0001" />
        </inertial>
        <visual>
            <origin xyz="0 0.0031 0" rpy="0 -0 0" />
            <geometry>
                <mesh filename="package://so_arm100_description/meshes/15657.stl" scale="1 1 1" />
            </geometry>
            <material name="0.917647_0.917647_0.917647_0.000000_0.000000">
                <texture />
                <color rgba="0.917647 0.917647 0.917647 1" />
            </material>
        </visual>
    </link>
    <link name="Passive horn_1">
        <inertial>
            <mass value="0.01" />
            <origin xyz="2.25823e-20 0.00200132 -8.39298e-21" rpy="0 -0 0" />
            <inertia ixx="0.0001" ixy="0.0" ixz="0.0" iyy="0.0001" iyz="0.0" izz="0.0001" />
        </inertial>
        <visual>
            <origin xyz="0 0.0031 0" rpy="0 -0 0" />
            <geometry>
                <mesh filename="package://so_arm100_description/meshes/15657.stl" scale="1 1 1" />
            </geometry>
            <material name="0.917647_0.917647_0.917647_0.000000_0.000000">
                <texture />
                <color rgba="0.917647 0.917647 0.917647 1" />
            </material>
        </visual>
    </link>
    <link name="Passive horn_2">
        <inertial>
            <mass value="0.01" />
            <origin xyz="2.25823e-20 0.00200132 -8.39298e-21" rpy="0 -0 0" />
            <inertia ixx="0.0001" ixy="0.0" ixz="0.0" iyy="0.0001" iyz="0.0" izz="0.0001" />
        </inertial>
        <visual>
            <origin xyz="0 0.0031 0" rpy="0 -0 0" />
            <geometry>
                <mesh filename="package://so_arm100_description/meshes/15657.stl" scale="1 1 1" />
            </geometry>
            <material name="0.917647_0.917647_0.917647_0.000000_0.000000">
                <texture />
                <color rgba="0.917647 0.917647 0.917647 1" />
            </material>
        </visual>
    </link>
    <link name="Passive horn_3">
        <inertial>
            <mass value="0.01" />
            <origin xyz="2.25823e-20 0.00200132 -8.39298e-21" rpy="0 -0 0" />
            <inertia ixx="0.0001" ixy="0.0" ixz="0.0" iyy="0.0001" iyz="0.0" izz="0.0001" />
        </inertial>
        <visual>
            <origin xyz="0 0.0031 0" rpy="0 -0 0" />
            <geometry>
                <mesh filename="package://so_arm100_description/meshes/15657.stl" scale="1 1 1" />
            </geometry>
            <material name="0.917647_0.917647_0.917647_0.000000_0.000000">
                <texture />
                <color rgba="0.917647 0.917647 0.917647 1" />
            </material>
        </visual>
    </link>
    <link name="Passive horn_4">
        <inertial>
            <mass value="0.01" />
            <origin xyz="2.25823e-20 0.00200132 -8.39298e-21" rpy="0 -0 0" />
            <inertia ixx="0.0001" ixy="0.0" ixz="0.0" iyy="0.0001" iyz="0.0" izz="0.0001" />
        </inertial>
        <visual>
            <origin xyz="0 0.0031 0" rpy="0 -0 0" />
            <geometry>
                <mesh filename="package://so_arm100_description/meshes/15657.stl" scale="1 1 1" />
            </geometry>
            <material name="0.917647_0.917647_0.917647_0.000000_0.000000">
                <texture />
                <color rgba="0.917647 0.917647 0.917647 1" />
            </material>
        </visual>
    </link>
    <link name="Passive horn_5">
        <inertial>
            <mass value="0.01" />
            <origin xyz="2.25823e-20 0.00200132 -8.39298e-21" rpy="0 -0 0" />
            <inertia ixx="0.0001" ixy="0.0" ixz="0.0" iyy="0.0001" iyz="0.0" izz="0.0001" />
        </inertial>
        <visual>
            <origin xyz="0 0.0031 0" rpy="0 -0 0" />
            <geometry>
                <mesh filename="package://so_arm100_description/meshes/15657.stl" scale="1 1 1" />
            </geometry>
            <material name="0.917647_0.917647_0.917647_0.000000_0.000000">
                <texture />
                <color rgba="0.917647 0.917647 0.917647 1" />
            </material>
        </visual>
    </link>
    <link name="Rotation_Pitch_08i">
        <inertial>
            <mass value="0.0857558" />
            <origin xyz="-0.0315559 0.00027158 0.0288595" rpy="0 -0 0" />
            <inertia ixx="0.0001" ixy="0.0" ixz="5.73361e-06" iyy="0.0001" iyz="0.0" izz="0.0001" />
        </inertial>
        <visual>
            <origin xyz="0.012 2.63299e-18 -0.01" rpy="0 -0 0" />
            <geometry>
                <mesh filename="package://so_arm100_description/meshes/78.stl" scale="1 1 1" />
            </geometry>
            <material name="0.329412_0.788235_0.113725_0.000000_0.000000">
                <texture />
                <color rgba="0.329412 0.788235 0.113725 1" />
            </material>
        </visual>
        <collision><origin xyz="-0.02 0 0.02" rpy="0 0 0" /><geometry><box size="0.05 0.03 0.05" /></geometry></collision>
    </link>
    <link name="SO_ARM100_08k_116_Square">
        <inertial>
            <mass value="0.157743" />
            <origin xyz="-0.0580146 0.0196995 -0.000365426" rpy="0 -0 0" />
            <inertia ixx="0.0001" ixy="-1.29876e-06" ixz="-2.64837e-06" iyy="0.000199145" iyz="0.0" izz="0.000260277" />
        </inertial>
        <visual>
            <origin xyz="-0.065085 0.0197 -0.012" rpy="0 -0 0" />
            <geometry>
                <mesh filename="package://so_arm100_description/meshes/106.stl" scale="1 1 1" />
            </geometry>
            <material name="0.329412_0.788235_0.113725_0.000000_0.000000">
                <texture />
                <color rgba="0.329412 0.788235 0.113725 1" />
            </material>
        </visual>
        <collision><origin xyz="-0.06 0.02 0" rpy="0 1.5708 0" /><geometry><box size="0.035 0.035 0.12" /></geometry></collision>
    </link>
    <link name="SO_ARM100_08k_Asym_Mirror_Clip">
        <inertial>
            <mass value="0.0172819" />
            <origin xyz="0.0011418 0.0231502 -0.00949422" rpy="0 -0 0" />
            <inertia ixx="0.0001" ixy="0.0" ixz="0.0" iyy="0.0001" iyz="0.0" izz="0.0001" />
        </inertial>
        <visual>
            <origin xyz="0.0410499 0.0232 0.02695" rpy="0 -0 0" />
            <geometry>
                <mesh filename="package://so_arm100_description/meshes/88.stl" scale="1 1 1" />
            </geometry>
            <material name="0.329412_0.788235_0.113725_0.000000_0.000000">
                <texture />
                <color rgba="0.329412 0.788235 0.113725 1" />
            </material>
        </visual>
    </link>
    <link name="SO_ARM100_08k_Mirror">
        <inertial>
            <mass value="0.0172819" />
            <origin xyz="0.0011418 0.0231502 -0.00949422" rpy="0 -0 0" />
            <inertia ixx="0.0001" ixy="0.0" ixz="0.0" iyy="0.0001" iyz="0.0" izz="0.0001" />
        </inertial>
        <visual>
            <origin xyz="0.0410499 0.0232 0.02695" rpy="0 -0 0" />
            <geometry>
                <mesh filename="package://so_arm100_description/meshes/59.stl" scale="1 1 1" />
            </geometry>
            <material name="0.329412_0.788235_0.113725_0.000000_0.000000">
                <texture />
                <color rgba="0.329412 0.788235 0.113725 1" />
            </material>
        </visual>
    </link>
    <link name="SO_ARM100_08k_Mirror_1">
        <inertial>
            <mass value="0.122407" />
            <origin xyz="-0.0561004 0.0130887 0.000468506" rpy="0 -0 0" />
            <inertia ixx="0.0001" ixy="1.47088e-05" ixz="2.22632e-06" iyy="0.000117598" iyz="0.0" izz="0.000154444" />
        </inertial>
        <visual>
            <origin xyz="-0.0648499 0.0182 0.032" rpy="0 -0 0" />
            <geometry>
                <mesh filename="package://so_arm100_description/meshes/96.stl" scale="1 1 1" />
            </geometry>
            <material name="0.329412_0.788235_0.113725_0.000000_0.000000">
                <texture />
                <color rgba="0.329412 0.788235 0.113725 1" />
            </material>
        </visual>
        <collision><origin xyz="-0.055 0.013 0" rpy="0 1.5708 0" /><geometry><box size="0.035 0.035 0.11" /></geometry></collision>
    </link>
    <link name="STS3215 Servo">
        <inertial>
            <mass value="0.036665" />
            <origin xyz="0.0218843 0.017001 0.007" rpy="0 -0 0" />
            <inertia ixx="0.0001" ixy="0.0" ixz="0.0" iyy="0.0001" iyz="0.0" izz="0.0001" />
        </inertial>
        <visual>
            <origin xyz="0.0227 0.017 0.007" rpy="0 -0 0" />
            <geometry>
                <mesh filename="package://so_arm100_description/meshes/15653.stl" scale="1 1 1" />
            </geometry>
            <material name="0.301961_0.301961_0.301961_0.000000_0.000000">
                <texture />
                <color rgba="0.301961 0.301961 0.301961 1" />
            </material>
        </visual>
    </link>
    <link name="STS3215 Servo_1">
        <inertial>
            <mass value="0.036665" />
            <origin xyz="0.0194843 -0.015899 -0.01025" rpy="0 -0 0" />
            <inertia ixx="0.0001" ixy="0.0" ixz="0.0" iyy="0.0001" iyz="0.0" izz="0.0001" />
        </inertial>
        <visual>
            <origin xyz="0.0203 -0.0159 -0.01025" rpy="0 -0 0" />
            <geometry>
                <mesh filename="package://so_arm100_description/meshes/15653.stl" scale="1 1 1" />
            </geometry>
            <material name="0.301961_0.301961_0.301961_0.000000_0.000000">
                <texture />
                <color rgba="0.301961 0.301961 0.301961 1" />
            </material>
        </visual>
    </link>
    <link name="STS3215 Servo_2">
        <inertial>
            <mass value="0.036665" />
            <origin xyz="0.0156843 0.015901 0.01025" rpy="0 -0 0" />
            <inertia ixx="0.0001" ixy="0.0" ixz="0.0" iyy="0.0001" iyz="0.0" izz="0.0001" />
        </inertial>
        <visual>
            <origin xyz="0.0165 0.0159 0.01025" rpy="0 -0 0" />
            <geometry>
                <mesh filename="package://so_arm100_description/meshes/15653.stl" scale="1 1 1" />
            </geometry>
            <material name="0.301961_0.301961_0.301961_0.000000_0.000000">
                <texture />
                <color rgba="0.301961 0.301961 0.301961 1" />
            </material>
        </visual>
    </link>
    <link name="STS3215 Servo_3">
        <inertial>
            <mass value="0.036665" />
            <origin xyz="0.0218843 0.017001 0.007" rpy="0 -0 0" />
            <inertia ixx="0.0001" ixy="0.0" ixz="0.0" iyy="0.0001" iyz="0.0" izz="0.0001" />
        </inertial>
        <visual>
            <origin xyz="0.0227 0.017 0.007" rpy="0 -0 0" />
            <geometry>
                <mesh filename="package://so_arm100_description/meshes/15653.stl" scale="1 1 1" />
            </geometry>
            <material name="0.301961_0.301961_0.301961_0.000000_0.000000">
                <texture />
                <color rgba="0.301961 0.301961 0.301961 1" />
            </material>
        </visual>
    </link>
    <link name="STS3215 Servo_4">
        <inertial>
            <mass value="0.036665" />
            <origin xyz="0.0218843 0.017001 -0.007" rpy="0 -0 0" />
            <inertia ixx="0.0001" ixy="0.0" ixz="0.0" iyy="0.0001" iyz="0.0" izz="0.0001" />
        </inertial>
        <visual>
            <origin xyz="0.0227 0.017 -0.007" rpy="0 -0 0" />
            <geometry>
                <mesh filename="package://so_arm100_description/meshes/15653.stl" scale="1 1 1" />
            </geometry>
            <material name="0.301961_0.301961_0.301961_0.000000_0.000000">
                <texture />
                <color rgba="0.301961 0.301961 0.301961 1" />
            </material>
        </visual>
    </link>
    <link name="STS3215 Servo_5">
        <inertial>
            <mass value="0.036665" />
            <origin xyz="0.0218843 0.017001 5.04921e-13" rpy="0 -0 0" />
            <inertia ixx="0.0001" ixy="0.0" ixz="0.0" iyy="0.0001" iyz="0.0" izz="0.0001" />
        </inertial>
        <visual>
            <origin xyz="0.0227 0.017 2.60209e-18" rpy="0 -0 0" />
            <geometry>
                <mesh filename="package://so_arm100_description/meshes/15653.stl" scale="1 1 1" />
            </geometry>
            <material name="0.301961_0.301961_0.301961_0.000000_0.000000">
                <texture />
                <color rgba="0.301961 0.301961 0.301961 1" />
            </material>
        </visual>
    </link>
    <link name="Socket button head screw M3x0_5 x 5">
        <inertial>
            <mass value="0.01" />
            <origin xyz="6.61508e-19 3.12115e-20 -0.00123552" rpy="0 -0 0" />
            <inertia ixx="0.0001" ixy="0.0" ixz="0.0" iyy="0.0001" iyz="0.0" izz="0.0001" />
        </inertial>
        <visual>
            <origin xyz="5.68017e-19 -5.28847e-35 0.00165" rpy="0 -0 0" />
            <geometry>
                <mesh filename="package://so_arm100_description/meshes/15649.stl" scale="1 1 1" />
            </geometry>
            <material name="0.603922_0.647059_0.686275_0.000000_0.000000">
                <texture />
                <color rgba="0.603922 0.647059 0.686275 1" />
            </material>
        </visual>
    </link>
    <link name="Socket button head screw M3x0_5 x 5_1">
        <inertial>
            <mass value="0.01" />
            <origin xyz="6.61508e-19 3.12115e-20 -0.00123552" rpy="0 -0 0" />
            <inertia ixx="0.0001" ixy="0.0" ixz="0.0" iyy="0.0001" iyz="0.0" izz="0.0001" />
        </inertial>
        <visual>
            <origin xyz="5.68017e-19 -5.28847e-35 0.00165" rpy="0 -0 0" />
            <geometry>
                <mesh filename="package://so_arm100_description/meshes/15649.stl" scale="1 1 1" />
            </geometry>
            <material name="0.603922_0.647059_0.686275_0.000000_0.000000">
                <texture />
                <color rgba="0.603922 0.647059 0.686275 1" />
            </material>
        </visual>
    </link>
    <link name="Socket button head screw M3x0_5 x 5_2">
        <inertial>
            <mass value="0.01" />
            <origin xyz="6.61508e-19 3.12115e-20 -0.00123552" rpy="0 -0 0" />
            <inertia ixx="0.0001" ixy="0.0" ixz="0.0" iyy="0.0001" iyz="0.0" izz="0.0001" />
        </inertial>
        <visual>
            <origin xyz="5.68017e-19 -5.28847e-35 0.00165" rpy="0 -0 0" />
            <geometry>
                <mesh filename="package://so_arm100_description/meshes/15649.stl" scale="1 1 1" />
            </geometry>
            <material name="0.603922_0.647059_0.686275_0.000000_0.000000">
                <texture />
                <color rgba="0.603922 0.647059 0.686275 1" />
            </material>
        </visual>
    </link>
    <link name="Socket button head screw M3x0_5 x 5_3">
        <inertial>
            <mass value="0.01" />
            <origin xyz="6.61508e-19 3.12115e-20 -0.00123552" rpy="0 -0 0" />
            <inertia ixx="0.0001" ixy="0.0" ixz="0.0" iyy="0.0001" iyz="0.0" izz="0.0001" />
        </inertial>
        <visual>
            <origin xyz="5.68017e-19 -5.28847e-35 0.00165" rpy="0 -0 0" />
            <geometry>
                <mesh filename="package://so_arm100_description/meshes/15649.stl" scale="1 1 1" />
            </geometry>
            <material name="0.603922_0.647059_0.686275_0.000000_0.000000">
                <texture />
                <color rgba="0.603922 0.647059 0.686275 1" />
            </material>
        </visual>
    </link>
    <link name="Socket button head screw M3x0_5 x 5_4">
        <inertial>
            <mass value="0.01" />
            <origin xyz="6.61508e-19 3.12115e-20 -0.00123552" rpy="0 -0 0" />
            <inertia ixx="0.0001" ixy="0.0" ixz="0.0" iyy="0.0001" iyz="0.0" izz="0.0001" />
        </inertial>
        <visual>
            <origin xyz="5.68017e-19 -5.28847e-35 0.00165" rpy="0 -0 0" />
            <geometry>
                <mesh filename="package://so_arm100_description/meshes/15649.stl" scale="1 1 1" />
            </geometry>
            <material name="0.603922_0.647059_0.686275_0.000000_0.000000">
                <texture />
                <color rgba="0.603922 0.647059 0.686275 1" />
            </material>
        </visual>
    </link>
    <link name="Socket button head screw M3x0_5 x 5_5">
        <inertial>
            <mass value="0.01" />
            <origin xyz="6.61508e-19 3.12115e-20 -0.00123552" rpy="0 -0 0" />
            <inertia ixx="0.0001" ixy="0.0" ixz="0.0" iyy="0.0001" iyz="0.0" izz="0.0001" />
        </inertial>
        <visual>
            <origin xyz="5.68017e-19 -5.28847e-35 0.00165" rpy="0 -0 0" />
            <geometry>
                <mesh filename="package://so_arm100_description/meshes/15649.stl" scale="1 1 1" />
            </geometry>
            <material name="0.603922_0.647059_0.686275_0.000000_0.000000">
                <texture />
                <color rgba="0.603922 0.647059 0.686275 1" />
            </material>
        </visual>
    </link>
    <link name="Wrist_Roll_08c">
        <inertial>
            <mass value="0.0711747" />
            <origin xyz="-0.0137632 -0.0293058 -0.00059286" rpy="0 -0 0" />
            <inertia ixx="0.0001" ixy="-8.87148e-06" ixz="0.0" iyy="0.0001" iyz="0.0" izz="0.0001" />
        </inertial>
        <visual>
            <origin xyz="0 0 0" rpy="0 -0 0" />
            <geometry>
                <mesh filename="package://so_arm100_description/meshes/92.stl" scale="1 1 1" />
            </geometry>
            <material name="0.329412_0.788235_0.113725_0.000000_0.000000">
                <texture />
                <color rgba="0.329412 0.788235 0.113725 1" />
            </material>
        </visual>
        <collision><origin xyz="-0.014 -0.02 0" rpy="0 0 0" /><geometry><box size="0.035 0.05 0.035" /></geometry></collision>
    </link>
    <link name="Wrist_Roll_Pitch_08i">
        <inertial>
            <mass value="0.0380917" />
            <origin xyz="-0.0148098 0.0263799 -5.10823e-05" rpy="0 -0 0" />
            <inertia ixx="0.0001" ixy="-1.06937e-06" ixz="0.0" iyy="0.0001" iyz="0.0" izz="0.0001" />
        </inertial>
        <visual>
            <origin xyz="-0.0181 0.028 4.0341e-18" rpy="0 -0 0" />
            <geometry>
                <mesh filename="package://so_arm100_description/meshes/110.stl" scale="1 1 1" />
            </geometry>
            <material name="0.329412_0.788235_0.113725_0.000000_0.000000">
                <texture />
                <color rgba="0.329412 0.788235 0.113725 1" />
            </material>
        </visual>
        <collision><origin xyz="-0.015 0.02 0" rpy="0 0 0" /><geometry><box size="0.035 0.05 0.035" /></geometry></collision>
    </link>
  <link name="root" />
    <joint name="shoulder_pan_joint" type="revolute">
        <origin xyz="0 0.0031 -3.78774e-17" rpy="-1.5708 -1.22173 -3.14159" />
        <axis xyz="0 0 1" />
        <parent link="Passive horn_5" />
        <child link="Rotation_Pitch_08i" />
  
    <limit lower="-3.14159" upper="3.14159" effort="2.0" velocity="1.0" />
    <dynamics damping="100.0" friction="10.0" />
  </joint>
    <joint name="shoulder_lift_joint" type="revolute">
        <origin xyz="1.38778e-17 -0.004 0" rpy="-3.14159 -0.785398 3.14159" />
        <axis xyz="0 1 0" />
        <parent link="Driven horn" />
        <child link="SO_ARM100_08k_116_Square" />
  
    <limit lower="-1.5708" upper="1.5708" effort="2.0" velocity="1.0" />
    <dynamics damping="100.0" friction="10.0" />
  </joint>
    <joint name="elbow_flex_joint" type="revolute">
        <origin xyz="-2.77556e-17 -0.004 2.77556e-17" rpy="-3.14159 -0.785398 -3.14159" />
        <axis xyz="0 1 0" />
        <parent link="Driven horn_4" />
        <child link="SO_ARM100_08k_Mirror_1" />
  
    <limit lower="-1.5708" upper="1.5708" effort="2.0" velocity="1.0" />
    <dynamics damping="100.0" friction="10.0" />
  </joint>
    <joint name="wrist_flex_joint" type="revolute">
        <origin xyz="0 -0.004 -2.77556e-17" rpy="1.5708 1.65978e-14 -1.5708" />
        <axis xyz="-1 0 0" />
        <parent link="Driven horn_3" />
        <child link="Wrist_Roll_Pitch_08i" />
  
    <limit lower="-1.5708" upper="1.5708" effort="1.0" velocity="1.0" />
    <dynamics damping="100.0" friction="10.0" />
  </joint>
    <joint name="wrist_roll_joint" type="revolute">
        <origin xyz="-6.93889e-18 -0.004 1.38778e-17" rpy="1.02838e-14 2.02115e-14 2.10942e-15" />
        <axis xyz="0 1 0" />
        <parent link="Driven horn_2" />
        <child link="Wrist_Roll_08c" />
  
    <limit lower="-3.14159" upper="3.14159" effort="1.0" velocity="1.0" />
    <dynamics damping="100.0" friction="10.0" />
  </joint>
    <joint name="gripper_joint" type="revolute">
        <origin xyz="1.38778e-17 -0.004 2.77556e-17" rpy="3.14159 -0.191986 -1.28291e-16" />
        <axis xyz="0 -1 9.53145e-17" />
        <parent link="Driven horn_1" />
        <child link="Moving_Jaw_08d" />
  
    <limit lower="0.0" upper="0.8" effort="0.5" velocity="1.0" />
    <dynamics damping="100.0" friction="10.0" />
  </joint>
    <joint name="Fastened 10_0" type="fixed">
        <origin xyz="-0.11957 0.0032 -0.0072" rpy="0 -1.5708 2.20243e-16" />
        <axis xyz="-1 0 0" />
        <parent link="SO_ARM100_08k_116_Square" />
        <child link="STS3215 Servo_4" />
    </joint>
    <joint name="Fastened 12_0" type="fixed">
        <origin xyz="-0.0996998 0.0016 0.0018" rpy="3.14159 -1.25537e-14 3.14159" />
        <axis xyz="-1 0 0" />
        <parent link="SO_ARM100_08k_Mirror_1" />
        <child link="STS3215 Servo_3" />
    </joint>
    <joint name="Fastened 15_0" type="fixed">
        <origin xyz="0.0109 0.0583 -0.01025" rpy="5.10787e-28 -8.44458e-19 3.14159" />
        <axis xyz="0 -1 0" />
        <parent link="Wrist_Roll_Pitch_08i" />
        <child link="STS3215 Servo_2" />
    </joint>
    <joint name="Fastened 17_0" type="fixed">
        <origin xyz="-0.013 -0.033875 0.016" rpy="1.5708 -2.57183e-15 6.56863e-15" />
        <axis xyz="0 -1 0" />
        <parent link="Wrist_Roll_08c" />
        <child link="STS3215 Servo_1" />
    </joint>
    <joint name="Fastened 2_1" type="fixed">
        <origin xyz="0.0352 0.0316 2.28058e-18" rpy="0 -0 0" />
        <axis xyz="0 1 0" />
        <parent link="STS3215 Servo_5" />
        <child link="Passive horn_5" />
    </joint>
    <joint name="Fastened 3_0" type="fixed">
        <origin xyz="0.0352 0.0023 0.007" rpy="2.77556e-17 -1.18329e-30 -1.35585e-31" />
        <axis xyz="0 -1 0" />
        <parent link="STS3215 Servo_3" />
        <child link="Driven horn_3" />
    </joint>
    <joint name="Fastened 3_1" type="fixed">
        <origin xyz="1.22887e-16 -0.01 0.0631" rpy="-1.5708 -1.11022e-16 -1.5708" />
        <axis xyz="-1 0 0" />
        <parent link="Base_08q_2" />
        <child link="STS3215 Servo_5" />
    </joint>
    <joint name="Fastened 3_3" type="fixed">
        <origin xyz="0.0328 -0.0306 -0.01025" rpy="2.37797e-60 -3.01443e-30 -1.57772e-30" />
        <axis xyz="0 -1 0" />
        <parent link="STS3215 Servo_1" />
        <child link="Driven horn_1" />
    </joint>
    <joint name="Fastened 3_4" type="fixed">
        <origin xyz="0.0352 0.0023 0.007" rpy="2.77556e-17 -1.06311e-31 -1.14015e-31" />
        <axis xyz="0 -1 0" />
        <parent link="STS3215 Servo" />
        <child link="Driven horn" />
    </joint>
    <joint name="Fastened 3_5" type="fixed">
        <origin xyz="0.029 0.0012 0.01025" rpy="-3.9443e-31 3.08149e-33 2.77556e-17" />
        <axis xyz="0 -1 0" />
        <parent link="STS3215 Servo_2" />
        <child link="Driven horn_2" />
    </joint>
    <joint name="Fastened 3_6" type="fixed">
        <origin xyz="0.0352 0.0023 -0.007" rpy="1.71597e-17 -1.47227e-34 1.71597e-17" />
        <axis xyz="0 -1 0" />
        <parent link="STS3215 Servo_4" />
        <child link="Driven horn_4" />
    </joint>
    <joint name="Fastened 7_0" type="fixed">
        <origin xyz="-0.0376 0.0167 0.0554" rpy="0 -1.5708 3.14159" />
        <axis xyz="-1 0 0" />
        <parent link="Rotation_Pitch_08i" />
        <child link="STS3215 Servo" />
    </joint>
    <joint name="fixed_node_to_root_joint_0" type="fixed">
        <origin xyz="0 0 0" rpy="0 -0 0" />
        <axis xyz="0 0 1" />
        <parent link="root" />
        <child link="Base_08q_2" />
    </joint>





  <gazebo>
    <plugin filename="libgazebo_ros2_control.so" name="gazebo_ros2_control">
      <parameters>/home/sonu/so_arm100_ws/install/so_arm100_description/share/so_arm100_description/config/ros2_controllers.yaml</parameters>
    </plugin>
  </gazebo>



  
  <link name="world" />
  <link name="camera_link">
    <inertial>
      <mass value="0.01" />
      <origin xyz="0 0 0" rpy="0 0 0" />
      <inertia ixx="0.0001" iyy="0.0001" izz="0.0001" ixy="0.0" ixz="0.0" iyz="0.0" />
    </inertial>
    <visual>
      <origin xyz="0 0 0" rpy="0 0 0" />
      <geometry><box size="0.03 0.03 0.03" /></geometry>
      <material name="black"><color rgba="0.1 0.1 0.1 1" /></material>
    </visual>
  </link>

  
  <gazebo reference="camera_link">
    <sensor type="camera" name="overhead_camera">
      <update_rate>30</update_rate>
      <camera name="head">
        <horizontal_fov>1.3962634</horizontal_fov>
        <image>
          <width>640</width>
          <height>480</height>
          <format>R8G8B8</format>
        </image>
        <clip>
          <near>0.02</near>
          <far>300</far>
        </clip>
      </camera>
      <plugin name="camera_controller" filename="libgazebo_ros_camera.so">
        <alwaysOn>true</alwaysOn>
        <updateRate>30</updateRate>
        <cameraName>overhead_camera</cameraName>
        <imageTopicName>image_raw</imageTopicName>
        <cameraInfoTopicName>camera_info</cameraInfoTopicName>
        <frameName>camera_link</frameName>
      </plugin>
    </sensor>
  </gazebo>


  <ros2_control name="GazeboSystem" type="system">
    <hardware>
      <plugin>gazebo_ros2_control/GazeboSystem</plugin>
    </hardware>
    <joint name="shoulder_pan_joint">
      <command_interface name="position">
        <param name="min">-3.14159</param>
        <param name="max">3.14159</param>
      </command_interface>
      <state_interface name="position" />
      <state_interface name="velocity" />
      <state_interface name="effort" />
    </joint>
    <joint name="shoulder_lift_joint">
      <command_interface name="position">
        <param name="min">-1.5708</param>
        <param name="max">1.5708</param>
      </command_interface>
      <state_interface name="position" />
      <state_interface name="velocity" />
      <state_interface name="effort" />
    </joint>
    <joint name="elbow_flex_joint">
      <command_interface name="position">
        <param name="min">-1.5708</param>
        <param name="max">1.5708</param>
      </command_interface>
      <state_interface name="position" />
      <state_interface name="velocity" />
      <state_interface name="effort" />
    </joint>
    <joint name="wrist_flex_joint">
      <command_interface name="position">
        <param name="min">-1.5708</param>
        <param name="max">1.5708</param>
      </command_interface>
      <state_interface name="position" />
      <state_interface name="velocity" />
      <state_interface name="effort" />
    </joint>
    <joint name="wrist_roll_joint">
      <command_interface name="position">
        <param name="min">-3.14159</param>
        <param name="max">3.14159</param>
      </command_interface>
      <state_interface name="position" />
      <state_interface name="velocity" />
      <state_interface name="effort" />
    </joint>
    <joint name="gripper_joint">
      <command_interface name="position">
        <param name="min">0.0</param>
        <param name="max">0.8</param>
      </command_interface>
      <state_interface name="position" />
      <state_interface name="velocity" />
      <state_interface name="effort" />
    </joint>
  </ros2_control>


  <gazebo reference="Base_08q_2">
    <self_collide>false</self_collide>
    <self_collide>false</self_collide>
  </gazebo>

  <gazebo reference="Rotation_Pitch_08i">
    <self_collide>false</self_collide>
    <self_collide>false</self_collide>
  </gazebo>

  <gazebo reference="SO_ARM100_08k_116_Square">
    <self_collide>false</self_collide>
    <self_collide>false</self_collide>
  </gazebo>

  <gazebo reference="SO_ARM100_08k_Mirror_1">
    <self_collide>false</self_collide>
    <self_collide>false</self_collide>
  </gazebo>

  <gazebo reference="Wrist_Roll_Pitch_08i">
    <self_collide>false</self_collide>
    <self_collide>false</self_collide>
  </gazebo>

  <gazebo reference="Wrist_Roll_08c">
    <self_collide>false</self_collide>
    <self_collide>false</self_collide>
  </gazebo>

  <gazebo reference="Moving_Jaw_08d">
    <self_collide>false</self_collide>
    <self_collide>false</self_collide>
  </gazebo>
</robot>